<?xml version="1.0"?>

<robot name="kuka_lwr_ee">
  <link name="Origin"/>
  <link name="linear_axis_x"/>
  <link name="linear_axis_y"/>
  <joint type="prismatic" name="axis_x">
    <parent link="Origin"/>
    <child link="linear_axis_x"/>
    <origin rpy="0 0 0" xyz="0 0 0"/>
    <axis xyz="1.0 0 0"/>
    <limit velocity="0.5" effort="150" lower="-0.92" upper="0.92"/>
  </joint>
  <joint type="prismatic" name="axis_y">
    <parent link="linear_axis_x"/>
    <child link="linear_axis_y"/>
    <origin rpy="0 0 0" xyz="0 0 0"/>
    <axis xyz="0 1.0 0"/>
    <limit velocity="0.5" effort="150" lower="-0.92" upper="0.92"/>
  </joint>
  <joint type="fixed" name="la_tcp">
    <parent link="linear_axis_y"/>
    <child link="base_link"/>
  </joint>
  <link name="base_link"/>
  <link name="base">
    <inertial>
      <mass value="2.7"/>
      <origin rpy="0 0 0" xyz="0 0 0.055"/>
      <inertia ixx="0.00603" ixy="0" ixz="0" iyy="0.00603" iyz="0" izz="0.006615"/>
    </inertial>
    <collision name="base_c0">
      <origin rpy="0 0 0" xyz="0 0 0.055"/>
      <geometry>
        <cylinder length="0.11" radius="0.07"/>
      </geometry>
      <!--surface_material: lwr_surface-->
    </collision>
    <visual name="vis0_lbr4_base">
      <origin rpy="0 0 0" xyz="0 0 0"/>
      <geometry>
        <mesh filename="package://euroc_c2_description/kuka_lwr/kuka-lwr-base.dae"/>
      </geometry>
    </visual>
  </link>
  <joint type="fixed" name="base_joint">
    <parent link="base_link"/>
    <child link="base"/>
  </joint>
  <link name="link1">
    <inertial>
      <mass value="2.7082"/>
      <origin rpy="0 0 0" xyz="0 0.01698 -0.05913"/>
      <inertia ixx="0.0123449" ixy="0" ixz="0" iyy="0.0123449" iyz="0" izz="3.9396351"/>
    </inertial>
    <collision name="link1_c0">
      <origin rpy="0 0 0" xyz="0 0 -0.1"/>
      <geometry>
        <cylinder length="0.2" radius="0.07"/>
      </geometry>
      <!--surface_material: lwr_surface-->
    </collision>
    <collision name="link1_c1">
      <origin rpy="0 0 0" xyz="0 0 0"/>
      <geometry>
        <sphere radius="0.1"/>
      </geometry>
      <!--surface_material: lwr_surface-->
    </collision>
    <visual name="vis0_lbr4_link1">
      <origin rpy="0 0 0" xyz="0 0 0"/>
      <geometry>
        <mesh filename="package://euroc_c2_description/kuka_lwr/kuka-lwr-link1.dae"/>
      </geometry>
    </visual>
  </link>
  <link name="link2">
    <inertial>
      <mass value="2.71"/>
      <origin rpy="0 0 0" xyz="0 0.1109 0.0141"/>
      <inertia ixx="0.0123531" ixy="0" ixz="0" iyy="0.0123531" iyz="0" izz="3.9396395"/>
    </inertial>
    <collision name="link2_c0">
      <origin rpy="-1.57079632679 0 0" xyz="0 0.1 0"/>
      <geometry>
        <cylinder length="0.2" radius="0.07"/>
      </geometry>
      <!--surface_material: lwr_surface-->
    </collision>
    <visual name="vis0_lbr4_link2">
      <origin rpy="0 0 0" xyz="0 0 0"/>
      <geometry>
        <mesh filename="package://euroc_c2_description/kuka_lwr/kuka-lwr-link2.dae"/>
      </geometry>
    </visual>
  </link>
  <link name="link3">
    <inertial>
      <mass value="2.5374"/>
      <origin rpy="0 0 0" xyz="0 -0.01628 0.06621"/>
      <inertia ixx="0.0115663" ixy="0" ixz="0" iyy="0.0115663" iyz="0" izz="1.5369966"/>
    </inertial>
    <collision name="link3_c0">
      <origin rpy="0 0 0" xyz="0 0 0.1"/>
      <geometry>
        <cylinder length="0.2" radius="0.07"/>
      </geometry>
      <!--surface_material: lwr_surface-->
    </collision>
    <collision name="link3_c1">
      <origin rpy="0 0 0" xyz="0 0 0.2"/>
      <geometry>
        <sphere radius="0.1"/>
      </geometry>
      <!--surface_material: lwr_surface-->
    </collision>
    <visual name="vis0_lbr4_link3">
      <origin rpy="0 0 0" xyz="0 0 0.2"/>
      <geometry>
        <mesh filename="package://euroc_c2_description/kuka_lwr/kuka-lwr-link3.dae"/>
      </geometry>
    </visual>
  </link>
  <link name="link4">
    <inertial>
      <mass value="2.5053"/>
      <origin rpy="0 0 0" xyz="0 -0.10538 0.01525"/>
      <inertia ixx="0.01142" ixy="0" ixz="0" iyy="0.01142" iyz="0" izz="1.536918"/>
    </inertial>
    <collision name="link4_c0">
      <origin rpy="-1.57079632679 0 0" xyz="0 -0.1 0"/>
      <geometry>
        <cylinder length="0.2" radius="0.07"/>
      </geometry>
      <!--surface_material: lwr_surface-->
    </collision>
    <visual name="vis0_lbr4_link4">
      <origin rpy="0 0 0" xyz="0 0 0"/>
      <geometry>
        <mesh filename="package://euroc_c2_description/kuka_lwr/kuka-lwr-link4.dae"/>
      </geometry>
    </visual>
  </link>
  <link name="link5">
    <inertial>
      <mass value="1.3028"/>
      <origin rpy="0 0 0" xyz="0 0.01566 0.12511"/>
      <inertia ixx="0.0055152" ixy="0" ixz="0" iyy="0.0055152" iyz="0" izz="0.6011519"/>
    </inertial>
    <collision name="link5_c0">
      <origin rpy="0 0 0" xyz="0 0 0.065"/>
      <geometry>
        <cylinder length="0.13" radius="0.07"/>
      </geometry>
      <!--surface_material: lwr_surface-->
    </collision>
    <visual name="vis0_lbr4_link5">
      <origin rpy="0 0 0" xyz="0 0 0.19"/>
      <geometry>
        <mesh filename="package://euroc_c2_description/kuka_lwr/kuka-lwr-link5.dae"/>
      </geometry>
    </visual>
  </link>
  <link name="link6">
    <inertial>
      <mass value="1.5686"/>
      <origin rpy="0 0 0" xyz="0 0.00283 -0.00228"/>
      <inertia ixx="0.0040156" ixy="0" ixz="0" iyy="0.0040156" iyz="0" izz="0.5783556"/>
    </inertial>
    <collision name="link6_c0">
      <origin rpy="0 0 0" xyz="0 -0.005 -0.0075"/>
      <geometry>
        <sphere radius="0.085"/>
      </geometry>
      <!--surface_material: lwr_surface-->
    </collision>
    <visual name="vis0_lbr4_link6">
      <origin rpy="0 0 0" xyz="0 0 0"/>
      <geometry>
        <mesh filename="package://euroc_c2_description/kuka_lwr/kuka-lwr-link6.dae"/>
      </geometry>
    </visual>
  </link>
  <link name="link7">
    <inertial>
      <mass value="0.1943"/>
      <origin rpy="0 0 0" xyz="0 0 0.06031"/>
      <inertia ixx="0.0000923" ixy="0" ixz="0" iyy="0.0000923" iyz="0" izz="0.5744954"/>
    </inertial>
    <collision name="link7_c0">
      <origin rpy="0 0 0" xyz="0 0 0.0685"/>
      <geometry>
        <cylinder length="0.023" radius="0.0405"/>
      </geometry>
      <!--surface_material: lwr_surface-->
    </collision>
    <visual name="vis0_lbr4_link7_apftn">
      <origin rpy="0 0 0" xyz="0 0 0"/>
      <material name="vis0_lbr4_link7_apftn_mat">
        <color rgba="0.176499992609 0.176499992609 0.176499992609 1"/>
      </material>
      <geometry>
        <mesh filename="package://euroc_c2_description/kuka_lwr/kuka-lwr-link7.dae"/>
      </geometry>
    </visual>
  </link>
  <joint type="revolute" name="lwr_joint_1">
    <parent link="base"/>
    <child link="link1"/>
    <origin rpy="0 0 0" xyz="0 0 0.31"/>
    <axis xyz="0 0 1"/>
    <limit velocity="1.7453" effort="150" lower="-2.96705972839" upper="2.96705972839"/>
  </joint>
  <joint type="revolute" name="lwr_joint_2">
    <parent link="link1"/>
    <child link="link2"/>
    <origin rpy="1.57079632679 0 0" xyz="0 0 0"/>
    <axis xyz="0 0 1"/>
    <limit velocity="1.7453" effort="150" lower="-2.09439510239" upper="2.09439510239"/>
  </joint>
  <joint type="revolute" name="lwr_joint_3">
    <parent link="link2"/>
    <child link="link3"/>
    <origin rpy="-1.57079632679 0 0" xyz="0 0.2 0"/>
    <axis xyz="0 0 1"/>
    <limit velocity="2.7925" effort="150" lower="-2.96705972839" upper="2.96705972839"/>
  </joint>
  <joint type="revolute" name="lwr_joint_4">
    <parent link="link3"/>
    <child link="link4"/>
    <origin rpy="-1.57079632679 0 0" xyz="0 0 0.2"/>
    <axis xyz="0 0 1"/>
    <limit velocity="2.7925" effort="150" lower="-2.09439510239" upper="2.09439510239"/>
  </joint>
  <joint type="revolute" name="lwr_joint_5">
    <parent link="link4"/>
    <child link="link5"/>
    <origin rpy="1.57079632679 0 0" xyz="0 -0.2 0"/>
    <axis xyz="0 0 1"/>
    <limit velocity="4.7124" effort="150" lower="-2.96705972839" upper="2.96705972839"/>
  </joint>
  <joint type="revolute" name="lwr_joint_6">
    <parent link="link5"/>
    <child link="link6"/>
    <origin rpy="1.57079632679 0 0" xyz="0 0 0.19"/>
    <axis xyz="0 0 1"/>
    <limit velocity="3.6652" effort="150" lower="-2.26892802759" upper="2.26892802759"/>
  </joint>
  <joint type="revolute" name="lwr_joint_7">
    <parent link="link6"/>
    <child link="link7"/>
    <origin rpy="-1.57079632679 0 0" xyz="0 0 0"/>
    <axis xyz="0 0 1"/>
    <limit velocity="3.6652" effort="150" lower="-2.96705972839" upper="2.96705972839"/>
  </joint>
  <link name="lwr_tcp"/>
  <joint type="fixed" name="lwr_tcp_joint">
    <parent link="link7"/>
    <child link="lwr_tcp"/>
  </joint>



  <link name="gripper_base">
    <inertial>
      <mass value="1.2"/>
      <origin rpy="0 0 0" xyz="0 0 -0.0465"/>
      <inertia ixx="0.0015538" ixy="0" ixz="0" iyy="0.0021193" iyz="0" izz="0.0019433"/>
    </inertial>
    <collision name="base_c0">
      <origin rpy="0 0 0" xyz="0 0 -0.0465"/>
      <geometry>
        <box size="0.112000 0.083000 0.093000"/>
      </geometry>
    </collision>
    <visual name="vis0_pg70_body">
      <origin rpy="0 0 0" xyz="0 0 0"/>
      <geometry>
        <mesh filename="package://euroc_c2_description/pg70_gripper/pg70_body.dae"/>
      </geometry>
    </visual>
  </link>
  <joint type="fixed" name="gripper_base_joint">
    <parent link="lwr_tcp"/>
    <child link="gripper_base"/>
    <origin rpy="3.1415927 0 0" xyz="0 0 0.08"/>
  </joint>
  <link name="finger2">
    <inertial>
      <mass value="0.1"/>
      <origin rpy="0 0 0" xyz="0.00953 0.00886 -0.09389"/>
      <inertia ixx="0.0000577" ixy="0" ixz="0" iyy="0.000061" iyz="0" izz="0.0000274"/>
    </inertial>
    <collision name="finger2_c0">
      <origin rpy="0 0 0" xyz="0.0045 0 -0.1235"/>
      <geometry>
        <box size="0.008500 0.030000 0.060000"/>
      </geometry>
      <!--surface_material: gripper_finger-->
    </collision>
    <collision name="finger2_c1">
      <origin rpy="0 0 0" xyz="-0.00025 0 -0.121"/>
      <geometry>
        <box size="0.003000 0.020000 0.055000"/>
      </geometry>
      <!--surface_material: gripper_finger_rubber-->
    </collision>
    <visual name="vis0_pg70_finger2">
      <origin rpy="0 0 0" xyz="0 0 0"/>
      <geometry>
        <mesh filename="package://euroc_c2_description/pg70_gripper/pg70_finger2.dae"/>
      </geometry>
    </visual>
  </link>
  <link name="finger1">
    <inertial>
      <mass value="0.1"/>
      <origin rpy="0 0 0" xyz="-0.00932 -0.00872 -0.09404"/>
      <inertia ixx="0.0000577" ixy="0" ixz="0" iyy="0.000061" iyz="0" izz="0.0000274"/>
    </inertial>
    <collision name="finger1_c0">
      <origin rpy="0 0 0" xyz="-0.0045 0 -0.1235"/>
      <geometry>
        <box size="0.008500 0.030000 0.060000"/>
      </geometry>
      <!--surface_material: gripper_finger-->
    </collision>
    <collision name="finger1_c1">
      <origin rpy="0 0 0" xyz="0.00025 0 -0.121"/>
      <geometry>
        <box size="0.003000 0.020000 0.055000"/>
      </geometry>
      <!--surface_material: gripper_finger_rubber-->
    </collision>
    <visual name="vis0_pg70_finger1">
      <origin rpy="0 0 0" xyz="0 0 0"/>
      <geometry>
        <mesh filename="package://euroc_c2_description/pg70_gripper/pg70_finger1.dae"/>
      </geometry>
    </visual>
  </link>
  <joint type="prismatic" name="joint_before_finger2">
    <parent link="gripper_base"/>
    <child link="finger2"/>
    <origin rpy="0 0 0" xyz="0.035 0 0"/>
    <axis xyz="1.0 0 0"/>
    <limit velocity="0.5" effort="150" lower="0" upper="0.035"/>
  </joint>
  <joint type="prismatic" name="joint_before_finger1">
    <parent link="gripper_base"/>
    <child link="finger1"/>
    <origin rpy="0 0 0" xyz="-0.0350 0 0"/>
    <axis xyz="1.0 0 0"/>
    <limit velocity="0.5" effort="150" lower="-0.035" upper="0"/>
  </joint>
  <link name="gripper_tcp"/>
  <joint type="fixed" name="gp_tcp_joint">
    <parent link="gripper_base"/>
    <child link="gripper_tcp"/>
    <origin rpy="-3.1415927 0 0" xyz="0 0 -0.093"/>
  </joint>
</robot>
