<?xml version="1.0"?>

<robot name="pg70_gripper">
  <link name="base_link"/>
  <link name="base">
    <inertial>
      <mass value="1.2"/>
      <origin rpy="0 0 0" xyz="0 0 -0.0465"/>
      <inertia ixx="0.0015538" ixy="0" ixz="0" iyy="0.0021193" iyz="0" izz="0.0019433"/>
    </inertial>
    <collision name="base_c0">
      <origin rpy="0 0 0" xyz="0 0 -0.0465"/>
      <geometry>
        <box size="0.112000 0.083000 0.093000"/>
      </geometry>
    </collision>
    <visual name="vis0_pg70_body">
      <origin rpy="0 0 0" xyz="0 0 0"/>
      <geometry>
        <mesh filename="package://euroc_c2_description/pg70_gripper/pg70_body.dae"/>
      </geometry>
    </visual>
  </link>
  <joint type="fixed" name="base_joint">
    <parent link="base_link"/>
    <child link="base"/>
  </joint>
  <link name="finger2">
    <inertial>
      <mass value="0.1"/>
      <origin rpy="0 0 0" xyz="0.00953 0.00886 -0.09389"/>
      <inertia ixx="0.0000577" ixy="0" ixz="0" iyy="0.000061" iyz="0" izz="0.0000274"/>
    </inertial>
    <collision name="finger2_c0">
      <origin rpy="0 0 0" xyz="0.0045 0 -0.1235"/>
      <geometry>
        <box size="0.008500 0.030000 0.060000"/>
      </geometry>
      <!--surface_material: gripper_finger-->
    </collision>
    <collision name="finger2_c1">
      <origin rpy="0 0 0" xyz="-0.00025 0 -0.121"/>
      <geometry>
        <box size="0.003000 0.020000 0.055000"/>
      </geometry>
      <!--surface_material: gripper_finger_rubber-->
    </collision>
    <visual name="vis0_pg70_finger2">
      <origin rpy="0 0 0" xyz="0 0 0"/>
      <geometry>
        <mesh filename="package://euroc_c2_description/pg70_gripper/pg70_finger2.dae"/>
      </geometry>
    </visual>
  </link>
  <link name="finger1">
    <inertial>
      <mass value="0.1"/>
      <origin rpy="0 0 0" xyz="-0.00932 -0.00872 -0.09404"/>
      <inertia ixx="0.0000577" ixy="0" ixz="0" iyy="0.000061" iyz="0" izz="0.0000274"/>
    </inertial>
    <collision name="finger1_c0">
      <origin rpy="0 0 0" xyz="-0.0045 0 -0.1235"/>
      <geometry>
        <box size="0.008500 0.030000 0.060000"/>
      </geometry>
      <!--surface_material: gripper_finger-->
    </collision>
    <collision name="finger1_c1">
      <origin rpy="0 0 0" xyz="0.00025 0 -0.121"/>
      <geometry>
        <box size="0.003000 0.020000 0.055000"/>
      </geometry>
      <!--surface_material: gripper_finger_rubber-->
    </collision>
    <visual name="vis0_pg70_finger1">
      <origin rpy="0 0 0" xyz="0 0 0"/>
      <geometry>
        <mesh filename="package://euroc_c2_description/pg70_gripper/pg70_finger1.dae"/>
      </geometry>
    </visual>
  </link>
  <joint type="prismatic" name="joint_before_finger2">
    <parent link="base"/>
    <child link="finger2"/>
    <origin rpy="0 0 0" xyz="0 0 0"/>
    <axis xyz="1.0 0 0"/>
    <limit velocity="1.6" effort="150" lower="0" upper="0.035"/>
  </joint>
  <joint type="prismatic" name="joint_before_finger1">
    <parent link="base"/>
    <child link="finger1"/>
    <origin rpy="0 0 0" xyz="0 0 0"/>
    <axis xyz="1.0 0 0"/>
    <limit velocity="1.6" effort="150" lower="-0.035" upper="0"/>
  </joint>
</robot>
